<?xml version="1.0"?>
<robot name="simple_diff_drive" xmlns:xacro="http://ros.org/wiki/xacro">

  <material name="blue">
    <color rgba="0 0 0.8 1"/>
  </material>
  <material name="black">
    <color rgba="0 0 0 1"/>
  </material>
  <material name="white">
    <color rgba="1 1 1 1"/>
  </material>

  <link name="base_link">
  </link>

  <joint name="chassis_joint" type="fixed">
    <parent link="base_link"/>
    <child link="chassis"/>
    <origin xyz="-0.1 0 0"/>
  </joint>

  <link name="chassis">
    <visual>
      <origin xyz="0.1 0 0.075"/>
      <geometry>
        <box size="0.3 0.3 0.15"/>
      </geometry>
      <material name="white"/>
    </visual>
    <collision>
      <origin xyz="0.1 0 0.075"/>
      <geometry>
        <box size="0.3 0.3 0.15"/>
      </geometry>
    </collision>
    <inertial>
      <origin xyz="0.1 0 0.075"/>
      <mass value="0.5"/>
      <inertia ixx="0.0046875" ixy="0.0" ixz="0.0" iyy="0.0046875" iyz="0.0" izz="0.0075"/>
    </inertial>
  </link>

  <joint name="left_wheel_joint" type="continuous">
    <parent link="base_link"/>
    <child link="left_wheel"/>
    <origin xyz="-0.1 0.175 0" rpy="-1.5708 0 0"/>
    <axis xyz="0 0 1"/>
  </joint>

  <link name="left_wheel">
    <visual>
      <geometry>
        <cylinder radius="0.05" length="0.04"/>
      </geometry>
      <material name="blue"/>
    </visual>
    <collision>
      <geometry>
        <cylinder radius="0.05" length="0.04"/>
      </geometry>
    </collision>
    <inertial>
      <mass value="0.1"/>
      <inertia ixx="0.00007583" ixy="0.0" ixz="0.0" iyy="0.00007583" iyz="0.0" izz="0.000125"/>
    </inertial>
  </link>

  <joint name="right_wheel_joint" type="continuous">
    <parent link="base_link"/>
    <child link="right_wheel"/>
    <origin xyz="-0.1 -0.175 0" rpy="-1.5708 0 0"/>
    <axis xyz="0 0 1"/>
  </joint>

  <link name="right_wheel">
    <visual>
      <geometry>
        <cylinder radius="0.05" length="0.04"/>
      </geometry>
      <material name="blue"/>
    </visual>
    <collision>
      <geometry>
        <cylinder radius="0.05" length="0.04"/>
      </geometry>
    </collision>
    <inertial>
      <mass value="0.1"/>
      <inertia ixx="0.00007583" ixy="0.0" ixz="0.0" iyy="0.00007583" iyz="0.0" izz="0.000125"/>
    </inertial>
  </link>

  <joint name="caster_joint" type="fixed">
    <parent link="chassis"/>
    <child link="caster_wheel"/>
    <origin xyz="0.2 0 0"/>
  </joint>

  <link name="caster_wheel">
    <visual>
      <geometry>
        <sphere radius="0.05"/>
      </geometry>
      <material name="black"/>
    </visual>
    <collision>
      <geometry>
        <sphere radius="0.05"/>
      </geometry>
    </collision>
    <inertial>
      <mass value="0.1"/>
      <inertia ixx="0.0001" ixy="0.0" ixz="0.0" iyy="0.0001" iyz="0.0" izz="0.0001"/>
    </inertial>
  </link>
    <joint name="camera_joint" type="fixed">
    	<parent link="chassis"/>
    	<child link="camera_link"/>
    	<origin xyz="0.25 0 0.175" rpy="0 0.3 0"/>
  	</joint>

  	<link name="camera_link">
    	<visual>
      		<geometry>
        		<box size="0.05 0.1 0.05"/>
      		</geometry>
      		<material name="red">
        		<color rgba="1 0 0 1"/>
      		</material>
    	</visual>
    	<collision>
      		<geometry>
        		<box size="0.05 0.1 0.05"/>
      		</geometry>
    	</collision>
    	<inertial>
      		<mass value="0.0001"/>
      		<inertia ixx="0.0001" ixy="0" ixz="0" iyy="0.0001" iyz="0" izz="0.0001"/>
		</inertial>
  	</link>

  	<joint name="camera_optical_joint" type="fixed">
    	<parent link="camera_link"/>
    	<child link="camera_link_optical"/>
    	<origin xyz="0 0 0" rpy="-1.5708 0 -1.5708"/>
  	</joint>
  	<link name="camera_link_optical"></link>
  	
  	<joint name="camera_counter_joint" type="fixed">
    	<parent link="chassis"/>
    	<child link="camera_counter_link"/>
    	<origin xyz="0.0 0 0.175" rpy="0 0.0 0"/>
  	</joint>

  	<link name="camera_counter_link">
    	<visual>
      		<geometry>
        		<box size="0.05 0.1 0.05"/>
      		</geometry>
      		<material name="red">
        		<color rgba="1 0 0 1"/>
      		</material>
    	</visual>
    	<collision>
      		<geometry>
        		<box size="0.05 0.1 0.05"/>
      		</geometry>
    	</collision>
    	<inertial>
      		<mass value="0.5"/>
      		<inertia ixx="0.0001" ixy="0" ixz="0" iyy="0.0001" iyz="0" izz="0.0001"/>
		</inertial>
  	</link>
  	
	<gazebo reference="camera_link">
		<sensor name="depth_camera" type="depth">
      		<update_rate>10</update_rate>
      		<topic>depth_camera</topic>
      		<camera>
        		<horizontal_fov>1.05</horizontal_fov>
				<optical_frame_id>camera_link</optical_frame_id>
        		<image>
          			<width>640</width>
          			<height>480</height>
          			<format>R8G8B8</format>
        		</image>
        		<clip>
          			<near>0.1</near>
          			<far>10.0</far>
        		</clip>
      		</camera>
      		<always_on>1</always_on>
      		<visualize>true</visualize>
    	</sensor>
	</gazebo>
  
  <gazebo>
    <plugin
      filename="gz-sim-diff-drive-system"
      name="gz::sim::systems::DiffDrive"
    >
      <left_joint>left_wheel_joint</left_joint>
      <right_joint>right_wheel_joint</right_joint>
      <wheel_separation>0.35</wheel_separation>
      <wheel_radius>0.05</wheel_radius>
      <topic>cmd_vel</topic>
    </plugin>
    <plugin
      filename="gz-sim-joint-state-publisher-system"
      name="gz::sim::systems::JointStatePublisher"
    >
      <topic>joint_states</topic>
    </plugin>
    <plugin
      filename="gz-sim-odometry-publisher-system"
      name="gz::sim::systems::OdometryPublisher"
    >
      <odom_publish_frequency>60</odom_publish_frequency>
      <odom_topic>odom</odom_topic>
      <odom_frame>odom</odom_frame>
      <robot_base_frame>base_link</robot_base_frame>
      <tf_topic>tf</tf_topic>
    </plugin>
  </gazebo>
</robot>
